# A2A-Minions Server Fixes Summary

## Issues Identified

1. **Schema Mismatch in Task Creation**
   - The `Task` model in `models.py` requires `sessionId` and `history` fields
   - The server's `create_task` method was not providing these required fields
   - This caused validation errors when creating tasks

2. **Incorrect ValidationError Handling**
   - The server was trying to raise a generic `ValidationError` with a custom message
   - Pydantic's `ValidationError` requires a specific constructor signature
   - This caused a `TypeError` when validation errors occurred

3. **Field Access Issues**
   - The `execute_task` method was trying to access `task["message"]` which doesn't exist in the new schema
   - The message is actually stored in `task["history"][0]`
   - The `created_at` timestamp was being accessed from the wrong location

## Fixes Implemented

### 1. Fixed Task Creation (server.py, lines 157-188)
```python
# Added proper Task creation with required fields:
task = Task(
    id=task_id,
    sessionId=session_id,  # New: Generated session ID
    status=TaskStatus(     # New: Proper TaskStatus object
        state=TaskState.SUBMITTED,
        timestamp=datetime.now().isoformat()
    ),
    history=[message],     # New: Initialize history with the message
    metadata=metadata.dict() if metadata else {},
    artifacts=[]
)
```

### 2. Fixed ValidationError Handling (server.py, multiple locations)
```python
# Changed from:
raise ValidationError(f"Invalid task parameters: {e}")

# To:
raise e  # Re-raise the original Pydantic ValidationError
```

### 3. Fixed Field Access Issues
- Updated `execute_task` to access message from `task["history"][0]`
- Updated `_cleanup_old_tasks` to access `created_at` from `task["metadata"]["created_at"]`

## Testing

A test script has been created (`test_fix.py`) to validate the fixes. To test:

1. Start the server:
   ```bash
   python apps/minions-a2a/run_server.py --port 8001 --api-key "abcd"
   ```

2. Run the test script:
   ```bash
   python test_fix.py
   ```

3. Run the full test suite:
   ```bash
   python apps/minions-a2a/tests/test_client_minions.py
   ```

## Impact

These fixes resolve:
- 400 Bad Request errors due to validation failures
- 500 Internal Server Error due to incorrect error handling
- Proper task creation and retrieval functionality

The server should now properly handle A2A protocol requests according to the expected schema.