# A2A-Minions Server Validation Error Fix Summary

## Issues Found

The server was experiencing validation errors when the test client sent requests. The main issues were:

### 1. Task Model Mismatch
The server's `create_task` method was creating Task objects with incorrect fields:

**What the Task model expects (from models.py):**
- `id`: str
- `sessionId`: str (required)
- `status`: TaskStatus object
- `history`: List[A2AMessage] (required)
- `metadata`: Optional[Dict[str, Any]]
- `artifacts`: List[Dict[str, Any]]

**What the server was trying to create:**
- `id`: str ✓
- `message`: A2AMessage (not in model)
- `metadata`: dict ✓
- `status`: dict (wrong type)
- `artifacts`: list ✓
- `created_at`: str (not in model)
- `created_by`: str (not in model)

### 2. ValidationError Handling Issue
In `_handle_send_task`, the code was trying to raise a ValidationError incorrectly:
```python
raise ValidationError(f"Invalid task parameters: {e}")
```
This failed because pydantic's ValidationError requires specific parameters.

### 3. Task Data Access Issues
- `execute_task` was trying to access `task["message"]` which didn't exist in the new structure
- `_cleanup_old_tasks` was accessing `task["created_at"]` directly instead of from metadata

## Fixes Applied

### 1. Fixed create_task Method (server.py, lines 148-184)
- Generate a session ID for each task
- Create initial history with the incoming message
- Use proper TaskStatus object instead of dict
- Move created_at and created_by into metadata
- Create Task with correct fields matching the model

### 2. Fixed ValidationError Handling (server.py, line 694)
- Changed to re-raise the original pydantic ValidationError directly

### 3. Fixed execute_task Method (server.py, line 203)
- Changed to extract message from `task["history"][0]` instead of `task["message"]`

### 4. Fixed update_task_status Method (server.py, lines 428-439)
- Create proper TaskStatus object instead of setting a dict

### 5. Fixed _cleanup_old_tasks Method (server.py, line 118-121)
- Access created_at from metadata: `task.get("metadata", {}).get("created_at")`

## Expected Result

With these fixes:
1. The server will properly validate incoming SendTaskParams
2. Tasks will be created with the correct structure matching the Task model
3. The test client should no longer receive 400 Bad Request validation errors
4. The 500 Internal Server Error from improper ValidationError handling is fixed

## Testing

To verify the fixes work:
1. Start the server: `python apps/minions-a2a/run_server.py --port 8001 --api-key "abcd"`
2. Run the test client: `python apps/minions-a2a/tests/test_client_minions.py`

The validation errors should be resolved and tests should proceed to actual task execution.